Workbook

Sheet Form Responses 7
A1: Timestamp | B1: Inspector Name | C1: Block | D1: Floor | E1: Flat | F1: Work Category | G1: RCC Work || Checklist [RCC-001 — Dimensions: length, breadth, depth as per drawing.] | H1: RCC Work || Checklist [RCC-002 — Check is the bar bending schedule is prepared and approved by the site Engineer.] | I1: RCC Work || Checklist [RCC-003 — Check for correct cutting & bending of bars as per approved BBS.] | J1: RCC Work || Checklist [RCC-004 — Check bar diameter, shapes of bar, dimension of bars & number of bars as per BBS.] | K1: RCC Work || Checklist [RCC-005 — Check identification tags is attached.] | L1: RCC Work || Checklist [RCC-006 — Check for cleanliness of bars from any oil, grease, soil & rust.] | M1: RCC Work || Checklist [RCC-007 — Check for satisfactory tying of reinforcement with binding wire.] | N1: RCC Work || Checklist [RCC-008 — Check for location of service conduits.] | O1: RCC Work || Checklist [RCC-009 — Check for readiness of reinforcement for release for concreting.] | P1: RCC Work || Checklist [RCC-010 — Slump test at pour location.] | Q1: RCC Work || Checklist [RCC-011 — Is continuous flow of concrete ensured.] | R1: RCC Work || Checklist [RCC-012 — Check for transportation & placement of concrete. Is it ok?] | S1: RCC Work || Checklist [RCC-013 — Check whether vibration being done till concrete packs tightly against all surface, reinforcement and embed...] | T1: RCC Work || Checklist [RCC-014 — Is blending of concrete poured in separated layers being ensured?] | U1: RCC Work || Checklist [RCC-015 — Is concrete consumed within initial setting time of cement.] | V1: RCC Work || Checklist [RCC-016 — Check for positions of construction joint. Is it ok?] | W1: RCC Work || Checklist [RCC-017 — Check for leveling and finishing of concrete surface.] | X1: RCC Work || Checklist [RCC-018 — Check the quantity of concrete of poured match with theoretical qty.] | Y1: RCC Work || Checklist [RCC-019 — Check the start time and end time of concreting.] | Z1: RCC Work || Checklist [RCC-020 — Cube samples cast (6 numbers / 50 m³).] | AA1: RCC Work || Checklist [RCC-021 — Shuttering material (ply / steel) condition.] | AB1: RCC Work || Checklist [RCC-022 — Line, level & plumb of formwork.] | AC1: RCC Work || Checklist [RCC-023 — Props, bracing & supports adequacy.] | AD1: RCC Work || Checklist [RCC-024 — Cleaning of formwork (no debris, dust, water).] | AE1: RCC Work || Checklist [RCC-025 — Shuttering oil / release agent application.] | AF1: RCC Work || Checklist [RCC-026 — Joints sealed (no slurry leakage points).] | AG1: RCC Work || Checklist [RCC-027 — Steel grade & make verification (TMT Fe-500/550D).] | AH1: RCC Work || Checklist [RCC-028 — Bar diameter, number & spacing as per BBS.] | AI1: RCC Work || Checklist [RCC-029 — Lap length & lap location.] | AJ1: RCC Work || Checklist [RCC-030 — Cover blocks (cement / PVC) — type, size, spacing.] | AK1: RCC Work || Checklist [RCC-031 — Clear cover provided.] | AL1: RCC Work || Checklist [RCC-032 — Hooks, bends, stirrups & ties.] | AM1: RCC Work || Checklist [RCC-033 — Chair bars in two-way reinforcement.] | AN1: RCC Work || Checklist [RCC-034 — Binding wire — coverage & tightness.] | AO1: RCC Work || Checklist [RCC-035 — Free of oil, mud, loose rust, paint.] | AP1: RCC Work || Checklist [RCC-036 — Electrical / plumbing conduits & sleeves in place.] | AQ1: RCC Work || Checklist [RCC-037 — Box-outs, pockets, inserts for fixtures.] | AR1: RCC Work || Checklist [RCC-038 — Construction joint preparation (laitance removed).] | AS1: RCC Work || Checklist [RCC-039 — Concrete grade & mix verification.] | AT1: RCC Work || Checklist [RCC-040 — Pour sequence & layering thickness.] | AU1: RCC Work || Checklist [RCC-041 — Vibration — needle / external.] | AV1: RCC Work || Checklist [RCC-042 — Free fall height of concrete.] | AW1: RCC Work || Checklist [RCC-043 — Top finishing — level, screeding, floating.] | AX1: RCC Work || Checklist [RCC-044 — Weather conditions monitored (temp/rain).] | AY1: RCC Work || Checklist [RCC-045 — Curing started within 6–12 hrs.] | AZ1: RCC Work || Checklist [RCC-046 — Shuttering striking time observed.] | BA1: RCC Work || Checklist [RCC-047 — Surface inspection — honeycomb, voids, cracks.] | BB1: Section Remarks [RCC Work] | BC1: Masonry Work || Checklist [MAS-001 — Check is the Drawing, Specification & method statement approved by the consultant.] | BD1: Masonry Work || Checklist [MAS-002 — Check whether type and material for Masonry work has been decided.] | BE1: Masonry Work || Checklist [MAS-003 — Check for availability of material as per the daily requirement.] | BF1: Masonry Work || Checklist [MAS-004 — Check is the area clean of loose material and concrete.] | BG1: Masonry Work || Checklist [MAS-005 — Check for proper staking of bricks / AAC block.] | BH1: Masonry Work || Checklist [MAS-006 — Check for quality of brick, cement & Sand.] | BI1: Masonry Work || Checklist [MAS-007 — Check for wetting of bricks.] | BJ1: Masonry Work || Checklist [MAS-008 — Check for the proportion of mortar mixing ratio.] | BK1: Masonry Work || Checklist [MAS-009 — Check for size of doors and window opening.] | BL1: Masonry Work || Checklist [MAS-010 — Check for margins left for plastering jobs.] | BM1: Masonry Work || Checklist [MAS-011 — Check for dry mixing on hard and clean surface before adding water to mix proportion of mortar.] | BN1: Masonry Work || Checklist [MAS-012 — Check for plumb, line & level.] | BO1: Masonry Work || Checklist [MAS-013 — Check for cleaning area for dead mortar and brick bat to location of disposal.] | BP1: Masonry Work || Checklist [MAS-014 — Check for raking of joints to received plaster/ pointing both side of the wall.] | BQ1: Masonry Work || Checklist [MAS-015 — Check for curing arrangements.] | BR1: Masonry Work || Checklist [MAS-016 — Check for defects if any urgently rectification required.] | BS1: Section Remarks [Masonry Work] | BT1: Excavation & Earthwork || Checklist [EXC-001 — Check whether soil investigation report/drawing studied by concerned Consultant.] | BU1: Excavation & Earthwork || Checklist [EXC-002 — Is excavation plan approved by Engineer/Consultant.] | BV1: Excavation & Earthwork || Checklist [EXC-003 — Check the layout, Alignment and size of excavation marked on the ground as per excavation plan.] | BW1: Excavation & Earthwork || Checklist [EXC-004 — Check Is there any underground utilities like sewers,water pipeline, cable etc is exist.] | BX1: Excavation & Earthwork || Checklist [EXC-005 — Check the area on excavation is clean & clear of bushes, vegetation & tree.] | BY1: Excavation & Earthwork || Checklist [EXC-006 — Check whether the excavated pit are adequately shored/timbered/safe slopes provided.] | BZ1: Excavation & Earthwork || Checklist [EXC-007 — Check where barricading & Caution signs are provided for deep excavation.] | CA1: Excavation & Earthwork || Checklist [EXC-008 — Check whether excavated material is kept away at least 1.5 mtr from the edge of the pit.] | CB1: Excavation & Earthwork || Checklist [EXC-009 — Make sure to keep away heavy equipment atleast 6.00 mtr from the pit.] | CC1: Excavation & Earthwork || Checklist [EXC-010 — Check lighting arrangement are adequate during night work.] | CD1: Excavation & Earthwork || Checklist [EXC-011 — Check the dewatering arrangement is available in case of pit is water logged.] | CE1: Section Remarks [Excavation & Earthwork] | CF1: Plaster & Waterproofing || Checklist [PLW-001 — Substrate cleaned of dust, oil, loose particles.] | CG1: Plaster & Waterproofing || Checklist [PLW-002 — Hacking of concrete surfaces (RCC / shear walls).] | CH1: Plaster & Waterproofing || Checklist [PLW-003 — Surface thoroughly wetted before plaster.] | CI1: Plaster & Waterproofing || Checklist [PLW-004 — Chicken wire mesh at RCC–masonry junctions.] | CJ1: Plaster & Waterproofing || Checklist [PLW-005 — All MEP chases filled, conduits secured & netted.] | CK1: Plaster & Waterproofing || Checklist [PLW-006 — Level pads / dots & screeds (gauges) installed.] | CL1: Plaster & Waterproofing || Checklist [PLW-007 — Cement — brand & grade.] | CM1: Plaster & Waterproofing || Checklist [PLW-008 — Sand — zone, silt content, washing.] | CN1: Plaster & Waterproofing || Checklist [PLW-009 — Water — potable, clean.] | CO1: Plaster & Waterproofing || Checklist [PLW-010 — Mix proportion as specified.] | CP1: Plaster & Waterproofing || Checklist [PLW-011 — Waterproofing admixture in external plaster.] | CQ1: Plaster & Waterproofing || Checklist [PLW-012 — Plaster thickness.] | CR1: Plaster & Waterproofing || Checklist [PLW-013 — Plumb, line & level (3m straight edge).] | CS1: Plaster & Waterproofing || Checklist [PLW-014 — Corners — sharp, true, with chamfer/groove if specified.] | CT1: Plaster & Waterproofing || Checklist [PLW-015 — Finish — smooth, no undulations, no cracks.] | CU1: Plaster & Waterproofing || Checklist [PLW-016 — Plaster in 2 coats (base + finish).] | CV1: Plaster & Waterproofing || Checklist [PLW-017 — Grooves at slab/wall junction & at intervals.] | CW1: Plaster & Waterproofing || Checklist [PLW-018 — Drip mould below projections / sunshade.] | CX1: Plaster & Waterproofing || Checklist [PLW-019 — Bands & architectural features as per elevation.] | CY1: Plaster & Waterproofing || Checklist [PLW-020 — Curing — minimum 7 days continuous.] | CZ1: Plaster & Waterproofing || Checklist [PLW-021 — Hollow sound check on cured plaster.] | DA1: Plaster & Waterproofing || Checklist [PLW-022 — Shrinkage / surface cracks.] | DB1: Plaster & Waterproofing || Checklist [PLW-023 — Joints between old & new plaster.] | DC1: Section Remarks [Plaster & Waterproofing] | DD1: Tile Work || Checklist [TIL-001 — Base / screed level & slope.] | DE1: Tile Work || Checklist [TIL-002 — Waterproofing completed & tested (wet areas).] | DF1: Tile Work || Checklist [TIL-003 — Substrate clean, dry, free of curing compound.] | DG1: Tile Work || Checklist [TIL-004 — Tile inspection — size, color, lot, shade match.] | DH1: Tile Work || Checklist [TIL-005 — Adhesive / mortar type.] | DI1: Tile Work || Checklist [TIL-006 — Tile spacers & spacing.] | DJ1: Tile Work || Checklist [TIL-007 — Grout — color, brand, epoxy/cementitious.] | DK1: Tile Work || Checklist [TIL-008 — Dry layout / setting-out approval.] | DL1: Tile Work || Checklist [TIL-009 — Reference lines & datum levels marked.] | DM1: Tile Work || Checklist [TIL-010 — Pattern, direction, design as per drawing.] | DN1: Tile Work || Checklist [TIL-011 — Full bedding — no voids under tiles.] | DO1: Tile Work || Checklist [TIL-012 — Lippage between adjacent tiles.] | DP1: Tile Work || Checklist [TIL-013 — Joints — straight, uniform, perpendicular.] | DQ1: Tile Work || Checklist [TIL-014 — Cut tiles — edge finish, location.] | DR1: Tile Work || Checklist [TIL-015 — Slope verification in toilet/balcony floor.] | DS1: Tile Work || Checklist [TIL-016 — Skirting / dado alignment with floor joints.] | DT1: Tile Work || Checklist [TIL-017 — Provision for expansion joints (large areas).] | DU1: Tile Work || Checklist [TIL-018 — Cutouts around pipes, fixtures, drains.] | DV1: Tile Work || Checklist [TIL-019 — Grouting — full depth, no gaps.] | DW1: Tile Work || Checklist [TIL-020 — Hollow sound test (tap with wooden mallet).] | DX1: Tile Work || Checklist [TIL-021 — Surface cleaning & polishing.] | DY1: Tile Work || Checklist [TIL-022 — Protection of finished tiles.] | DZ1: Section Remarks [Tile Work] | EA1: Putty Work || Checklist [PUT-001 — Plaster fully cured (min 21–28 days).] | EB1: Putty Work || Checklist [PUT-002 — Surface cleaning — dust, loose particles, oil.] | EC1: Putty Work || Checklist [PUT-003 — Hairline / minor cracks filled.] | ED1: Putty Work || Checklist [PUT-004 — Sanding of high spots / projections.] | EE1: Putty Work || Checklist [PUT-005 — Putty brand & type approved.] | EF1: Putty Work || Checklist [PUT-006 — Mixing ratio with water.] | EG1: Putty Work || Checklist [PUT-007 — Pot life observed.] | EH1: Putty Work || Checklist [PUT-008 — Number of coats.] | EI1: Putty Work || Checklist [PUT-009 — Thickness per coat.] | EJ1: Putty Work || Checklist [PUT-010 — Drying time between coats.] | EK1: Putty Work || Checklist [PUT-011 — Sanding between coats (320–400 grit).] | EL1: Putty Work || Checklist [PUT-012 — Edges, corners, junctions — neat finish.] | EM1: Putty Work || Checklist [PUT-013 — Surface smoothness (touch & oblique-light check).] | EN1: Putty Work || Checklist [PUT-014 — No pinholes, blowholes or cracks.] | EO1: Putty Work || Checklist [PUT-015 — Moisture content before paint.] | EP1: Putty Work || Checklist [PUT-016 — Final sanding & dust cleaning before primer.] | EQ1: Section Remarks [Putty Work] | ER1: Electrical Work || Checklist [ELE-001 — Conduit make, ISI marked, fire-retardant.] | ES1: Electrical Work || Checklist [ELE-002 — Conduit chasing — depth & alignment.] | ET1: Electrical Work || Checklist [ELE-003 — No diagonal chasing; no chasing in beams.] | EU1: Electrical Work || Checklist [ELE-004 — Conduit joints — couplers / solvent cement.] | EV1: Electrical Work || Checklist [ELE-005 — Bend radius.] | EW1: Electrical Work || Checklist [ELE-006 — Fish wire installed in every conduit.] | EX1: Electrical Work || Checklist [ELE-007 — Conduits secured with saddles / nails.] | EY1: Electrical Work || Checklist [ELE-008 — Switch / socket box position & height.] | EZ1: Electrical Work || Checklist [ELE-009 — Box flush with finished plaster level.] | FA1: Electrical Work || Checklist [ELE-010 — DB location, size, accessibility.] | FB1: Electrical Work || Checklist [ELE-011 — Earth bus bar & neutral bar in DB.] | FC1: Electrical Work || Checklist [ELE-012 — Cable brand, size, FRLS / ISI marking.] | FD1: Electrical Work || Checklist [ELE-013 — Cable colour code.] | FE1: Electrical Work || Checklist [ELE-014 — Cable sizes vs. circuit load.] | FF1: Electrical Work || Checklist [ELE-015 — No joints inside conduit.] | FG1: Electrical Work || Checklist [ELE-016 — Number of wires per conduit.] | FH1: Electrical Work || Checklist [ELE-017 — Looping at switch boards (phase looped, not neutral).] | FI1: Electrical Work || Checklist [ELE-018 — Earth pit construction & resistance.] | FJ1: Electrical Work || Checklist [ELE-019 — Earthing conductor size & continuity.] | FK1: Electrical Work || Checklist [ELE-020 — Double earthing for all 3-phase equipment.] | FL1: Electrical Work || Checklist [ELE-021 — RCCB / ELCB installation & rating.] | FM1: Electrical Work || Checklist [ELE-022 — MCB ratings vs. circuit design.] | FN1: Electrical Work || Checklist [ELE-023 — Insulation resistance (Megger) — 500V DC.] | FO1: Electrical Work || Checklist [ELE-024 — Continuity test — phase, neutral, earth.] | FP1: Electrical Work || Checklist [ELE-025 — Earth resistance test (clamp / fall-of-potential).] | FQ1: Electrical Work || Checklist [ELE-026 — Polarity test for sockets.] | FR1: Electrical Work || Checklist [ELE-027 — Load test of DB.] | FS1: Electrical Work || Checklist [ELE-028 — Functional test of all switches, sockets, lights.] | FT1: Electrical Work || Checklist [ELE-029 — Switch / socket plates — level, no gaps to wall.] | FU1: Electrical Work || Checklist [ELE-030 — Light fittings — alignment, level, firm fixing.] | FV1: Electrical Work || Checklist [ELE-031 — Ceiling fan — hook, downrod, balance.] | FW1: Electrical Work || Checklist [ELE-032 — DB labelling — circuit identification.] | FX1: Section Remarks [Electrical Work] | FY1: Plumbing Work || Checklist [PLB-001 — Pipe material, brand, ISI marking (CPVC/PPR).] | FZ1: Plumbing Work || Checklist [PLB-002 — Pipe sizing per fixture units.] | GA1: Plumbing Work || Checklist [PLB-003 — Concealed pipe routing & supports.] | GB1: Plumbing Work || Checklist [PLB-004 — Solvent cement joints / heat fusion (PPR).] | GC1: Plumbing Work || Checklist [PLB-005 — Hot & cold lines — separation & insulation.] | GD1: Plumbing Work || Checklist [PLB-006 — Hydrostatic pressure test (concealed lines).] | GE1: Plumbing Work || Checklist [PLB-007 — Isolation valves at branches & before fixtures.] | GF1: Plumbing Work || Checklist [PLB-008 — Air release & flushing of system.] | GG1: Plumbing Work || Checklist [PLB-009 — Pipe material (UPVC / SWR / cast iron).] | GH1: Plumbing Work || Checklist [PLB-010 — Pipe slope for horizontal runs.] | GI1: Plumbing Work || Checklist [PLB-011 — Traps under all fixtures (P/S/floor).] | GJ1: Plumbing Work || Checklist [PLB-012 — Vent pipe extension above roof.] | GK1: Plumbing Work || Checklist [PLB-013 — Floor traps & nahani trap — level with floor finish.] | GL1: Plumbing Work || Checklist [PLB-014 — Leakage test — water / smoke / air.] | GM1: Plumbing Work || Checklist [PLB-015 — Cleanouts / inspection openings.] | GN1: Plumbing Work || Checklist [PLB-016 — Fixture brand, model, color as approved.] | GO1: Plumbing Work || Checklist [PLB-017 — WC / wash basin / urinal fixing — level, firm.] | GP1: Plumbing Work || Checklist [PLB-018 — Tap & mixer installation — leak-free, aligned.] | GQ1: Plumbing Work || Checklist [PLB-019 — Shower fixing — height, alignment.] | GR1: Plumbing Work || Checklist [PLB-020 — Health faucet, angle valves, connectors.] | GS1: Plumbing Work || Checklist [PLB-021 — Sewer pipe material & dia.] | GT1: Plumbing Work || Checklist [PLB-022 — Bedding & backfill of buried pipes.] | GU1: Plumbing Work || Checklist [PLB-023 — Manhole construction — invert level, channel.] | GV1: Plumbing Work || Checklist [PLB-024 — Slope between manholes.] | GW1: Plumbing Work || Checklist [PLB-025 — Storm water drain — sizing & slope.] | GX1: Plumbing Work || Checklist [PLB-026 — Rain water down-takes & gratings.] | GY1: Plumbing Work || Checklist [PLB-027 — Rainwater harvesting pit / recharge bore.] | GZ1: Plumbing Work || Checklist [PLB-028 — First-flush diverter / silt trap.] | HA1: Plumbing Work || Checklist [PLB-029 — OHT & UGT — watertightness test.] | HB1: Plumbing Work || Checklist [PLB-030 — Pumps — make, capacity, head.] | HC1: Plumbing Work || Checklist [PLB-031 — Float switches, level controllers.] | HD1: Section Remarks [Plumbing Work] | HE1: False Ceiling Work || Checklist [FCL-001 — Ceiling level & layout marking.] | HF1: False Ceiling Work || Checklist [FCL-002 — MEP services above ceiling completed & tested.] | HG1: False Ceiling Work || Checklist [FCL-003 — Approved shop drawing with grid pattern.] | HH1: False Ceiling Work || Checklist [FCL-004 — Gypsum board / calcium silicate — brand, thickness.] | HI1: False Ceiling Work || Checklist [FCL-005 — GI sections — perimeter channel, intermediate, ceiling section.] | HJ1: False Ceiling Work || Checklist [FCL-006 — Suspension — soffit cleats, GI rods, hangers.] | HK1: False Ceiling Work || Checklist [FCL-007 — Screws — drywall screws, dry-rust treated.] | HL1: False Ceiling Work || Checklist [FCL-008 — Perimeter channel fixing.] | HM1: False Ceiling Work || Checklist [FCL-009 — Intermediate channel spacing.] | HN1: False Ceiling Work || Checklist [FCL-010 — Ceiling section spacing.] | HO1: False Ceiling Work || Checklist [FCL-011 — Level of grid (3m straightedge).] | HP1: False Ceiling Work || Checklist [FCL-012 — Cross bracing & rigidity.] | HQ1: False Ceiling Work || Checklist [FCL-013 — Joints staggered; no four-corner meeting.] | HR1: False Ceiling Work || Checklist [FCL-014 — Cut edges chamfered for taping.] | HS1: False Ceiling Work || Checklist [FCL-015 — Cut-outs for lights, AC grills, sprinklers.] | HT1: False Ceiling Work || Checklist [FCL-016 — Screw pattern & depth.] | HU1: False Ceiling Work || Checklist [FCL-017 — Joint taping (paper tape + jointing compound).] | HV1: False Ceiling Work || Checklist [FCL-018 — Corner beads at external corners.] | HW1: False Ceiling Work || Checklist [FCL-019 — Sanding & putty finish.] | HX1: False Ceiling Work || Checklist [FCL-020 — Inspection panels / access doors.] | HY1: False Ceiling Work || Checklist [FCL-021 — Painting — primer + 2 finish coats.] | HZ1: Section Remarks [False Ceiling Work] | IA1: Paint Work || Checklist [PNT-001 — The scaffolding to be self-standing and rigid.] | IB1: Paint Work || Checklist [PNT-002 — Check for double horizontals, wherever necessary.] | IC1: Paint Work || Checklist [PNT-003 — Check for telescopic vertical scaffolding.] | ID1: Paint Work || Checklist [PNT-004 — Check for diagonal bracings.] | IE1: Paint Work || Checklist [PNT-005 — Algae affected area is cleaned properly before commencing the painting work.] | IF1: Paint Work || Checklist [PNT-006 — Crack filling is done by good quality of exterior grade crack filler.] | IG1: Paint Work || Checklist [PNT-007 — Window frame tie be protected and wrapped with plastic sheet.] | IH1: Paint Work || Checklist [PNT-008 — Check all window jambs are properly repaired.] | II1: Paint Work || Checklist [PNT-009 — Check deck ceiling light points are cleared.] | IJ1: Paint Work || Checklist [PNT-010 — Cleaning of dust and loose particles.] | IK1: Paint Work || Checklist [PNT-011 — Check after polishing, primer coat with proper finish.] | IL1: Paint Work || Checklist [PNT-012 — Check 1st coat paint is applied.] | IM1: Paint Work || Checklist [PNT-013 — Check baking coat, patchiness, unevenness, brush mark not seen.] | IN1: Paint Work || Checklist [PNT-014 — Paint as per approved scheme.] | IO1: Paint Work || Checklist [PNT-015 — Surface fully cured & dry.] | IP1: Paint Work || Checklist [PNT-016 — Putty work completed & sanded smooth.] | IQ1: Paint Work || Checklist [PNT-017 — Paint brand, type, batch verification.] | IR1: Paint Work || Checklist [PNT-018 — Primer type matched to substrate.] | IS1: Paint Work || Checklist [PNT-019 — Color shade approved (shade card / mock-up).] | IT1: Paint Work || Checklist [PNT-020 — Thinning ratio per manufacturer.] | IU1: Paint Work || Checklist [PNT-021 — Primer — single coat, uniform.] | IV1: Paint Work || Checklist [PNT-022 — Finish coats — minimum 2 coats.] | IW1: Paint Work || Checklist [PNT-023 — Drying time between coats.] | IX1: Paint Work || Checklist [PNT-024 — DFT (Dry Film Thickness) verification.] | IY1: Paint Work || Checklist [PNT-025 — Uniform color, no brush/roller marks, no patches.] | IZ1: Paint Work || Checklist [PNT-026 — Cutting at edges — sharp clean lines.] | JA1: Paint Work || Checklist [PNT-027 — Weather conditions during application.] | JB1: Paint Work || Checklist [PNT-028 — External primer — alkali-resistant.] | JC1: Paint Work || Checklist [PNT-029 — Min 2 coats exterior emulsion / texture.] | JD1: Paint Work || Checklist [PNT-030 — Anti-fungal / anti-algal performance.] | JE1: Paint Work || Checklist [PNT-031 — Texture pattern uniformity (if textured).] | JF1: Paint Work || Checklist [PNT-032 — Edges & joints with adjoining materials.] | JG1: Paint Work || Checklist [PNT-033 — Scaffold mark touch-ups completed.] | JH1: Paint Work || Checklist [PNT-034 — Hardware, glass, frames protected during paint.] | JI1: Paint Work || Checklist [PNT-035 — Final inspection in daylight and artificial light.] | JJ1: Section Remarks [Paint Work] | JK1: Landscape Development || Checklist [LAN-001 — Site clearance — debris, weeds, construction waste.] | JL1: Landscape Development || Checklist [LAN-002 — Existing soil testing (pH, drainage).] | JM1: Landscape Development || Checklist [LAN-003 — Sub-grade levels & contouring.] | JN1: Landscape Development || Checklist [LAN-004 — Sub-surface drainage / weep holes.] | JO1: Landscape Development || Checklist [LAN-005 — Top soil quality & depth.] | JP1: Landscape Development || Checklist [LAN-006 — Organic manure / compost mixing.] | JQ1: Landscape Development || Checklist [LAN-007 — Plant species list — match approved schedule.] | JR1: Landscape Development || Checklist [LAN-008 — Plant health — disease-free, hardened.] | JS1: Landscape Development || Checklist [LAN-009 — Pit size for trees / shrubs / hedges.] | JT1: Landscape Development || Checklist [LAN-010 — Spacing between plants.] | JU1: Landscape Development || Checklist [LAN-011 — Staking & support for trees.] | JV1: Landscape Development || Checklist [LAN-012 — Grass species & laying method (sod/sprig).] | JW1: Landscape Development || Checklist [LAN-013 — Rolling & levelling of lawn.] | JX1: Landscape Development || Checklist [LAN-014 — Irrigation system — drip / sprinkler layout.] | JY1: Landscape Development || Checklist [LAN-015 — Water source, pumps, controllers.] | JZ1: Landscape Development || Checklist [LAN-016 — Pressure & flow check at extremities.] | KA1: Landscape Development || Checklist [LAN-017 — Pathways — material, level, slope.] | KB1: Landscape Development || Checklist [LAN-018 — Kerb stones — alignment, jointing.] | KC1: Landscape Development || Checklist [LAN-019 — Decorative elements (pergolas, benches, planters).] | KD1: Landscape Development || Checklist [LAN-020 — Garden lights / bollards / spike lights.] | KE1: Landscape Development || Checklist [LAN-021 — Cable laid in conduit, depth ≥ 600mm.] | KF1: Landscape Development || Checklist [LAN-022 — Earthing of metallic posts.] | KG1: Landscape Development || Checklist [LAN-023 — Plant survival rate during defects period.] | KH1: Landscape Development || Checklist [LAN-024 — Mulching, weeding, pruning schedule.] | KI1: Section Remarks [Landscape Development] | KJ1: Fire Fighting Work || Checklist [FIR-001 — Fire NOC / approved drawings on site.] | KK1: Fire Fighting Work || Checklist [FIR-002 — Equipment make & model as approved.] | KL1: Fire Fighting Work || Checklist [FIR-003 — Pipe material — MS heavy / GI as specified.] | KM1: Fire Fighting Work || Checklist [FIR-004 — Pipe routing & supports.] | KN1: Fire Fighting Work || Checklist [FIR-005 — Welded / flanged joints — quality.] | KO1: Fire Fighting Work || Checklist [FIR-006 — Pipe painting — fire red.] | KP1: Fire Fighting Work || Checklist [FIR-007 — Pipe identification & flow direction.] | KQ1: Fire Fighting Work || Checklist [FIR-008 — Wet riser size & location.] | KR1: Fire Fighting Work || Checklist [FIR-009 — Landing valves on each floor.] | KS1: Fire Fighting Work || Checklist [FIR-010 — Hose reel (rubber-lined) on each floor.] | KT1: Fire Fighting Work || Checklist [FIR-011 — Hose box & accessories.] | KU1: Fire Fighting Work || Checklist [FIR-012 — External yard hydrants.] | KV1: Fire Fighting Work || Checklist [FIR-013 — Sprinkler heads — type, K-factor, temp rating.] | KW1: Fire Fighting Work || Checklist [FIR-014 — Sprinkler spacing & coverage.] | KX1: Fire Fighting Work || Checklist [FIR-015 — Distance from wall / obstruction.] | KY1: Fire Fighting Work || Checklist [FIR-016 — Flow switch, test & drain valves.] | KZ1: Fire Fighting Work || Checklist [FIR-017 — Main fire pump — capacity & head.] | LA1: Fire Fighting Work || Checklist [FIR-018 — Jockey pump capacity.] | LB1: Fire Fighting Work || Checklist [FIR-019 — Diesel engine pump — fuel tank, battery.] | LC1: Fire Fighting Work || Checklist [FIR-020 — Pump auto-start at set pressure.] | LD1: Fire Fighting Work || Checklist [FIR-021 — Suction / delivery — gauges, NRV, gate valve.] | LE1: Fire Fighting Work || Checklist [FIR-022 — Dedicated fire water tank capacity.] | LF1: Fire Fighting Work || Checklist [FIR-023 — Low-level alarm & breather.] | LG1: Fire Fighting Work || Checklist [FIR-024 — Hydrostatic test on pipework.] | LH1: Fire Fighting Work || Checklist [FIR-025 — Flow & pressure test at remotest hydrant.] | LI1: Fire Fighting Work || Checklist [FIR-026 — Sprinkler trip test (each zone).] | LJ1: Fire Fighting Work || Checklist [FIR-027 — Fire alarm / detection — smoke, heat detectors.] | LK1: Fire Fighting Work || Checklist [FIR-028 — MCP (manual call point) — tested every floor.] | LL1: Fire Fighting Work || Checklist [FIR-029 — PA system & hooter audibility.] | LM1: Fire Fighting Work || Checklist [FIR-030 — Fire extinguishers — type, capacity, location.] | LN1: Fire Fighting Work || Checklist [FIR-031 — Mounting height & signage.] | LO1: Fire Fighting Work || Checklist [FIR-032 — Refill / inspection due date marked.] | LP1: Fire Fighting Work || Checklist [FIR-033 — Final fire department inspection & NOC.] | LQ1: Section Remarks [Fire Fighting Work] | LR1: Overall Site Remarks | LS1: Defect photos (name each file with its check ID)
A2: 46174.015 | B2: Mikayla Goodman | C2: 4 | D2: 5 | E2: B | F2: RCC Work | G2: OK | H2: OK | I2: OK | J2: OK | K2: OK | L2: OK | M2: OK | N2: OK | O2: OK | P2: OK | Q2: OK | R2: OK | S2: OK | T2: OK | U2: OK | V2: OK | W2: OK | X2: OK | Y2: OK | Z2: OK | AA2: OK | AB2: OK | AC2: OK | AD2: OK | AE2: OK | AF2: OK | AG2: OK | AH2: OK | AI2: OK | AJ2: OK | BB2: Cumque ratione sint | LS2: https://drive.google.com/open?id=1uD-Rcu9d8dhdJwtNeBqxAOgvrnHQTzXc
A3: 46174.017 | B3: Indigo Hood | C3: 6 | D3: Podium | E3: D | F3: Fire Fighting Work | LQ3: Molestiae odio volup | LR3: Odio quam numquam ea | LS3: https://drive.google.com/open?id=1zkLEw_IT4yqcFxTf6JRlpNM2gzDEZtph
A4: 46174.018 | B4: Isha Maji | C4: 5 | D4: 7 | E4: H | F4: Landscape Development | JK4: OK | JL4: OK | JM4: OK | JN4: OK | JO4: OK | JP4: OK | JQ4: OK | JR4: OK | JS4: OK | JT4: OK | JU4: OK | JV4: OK | JW4: OK | JX4: OK | JY4: OK | JZ4: OK | KA4: OK | KB4: OK | KC4: OK | KD4: OK | KE4: OK | KF4: OK | KG4: OK | KH4: OK | KI4: Very Good | LR4: Good | LS4: https://drive.google.com/open?id=1td6vtf3DnYjfEC1h4Ba09Q3-AGoHT_Lw
A5: 46174.059 | B5: Test Manash | C5: 2 | D5: 3 | E5: E | F5: RCC Work | G5: NOT OK | H5: NOT OK | I5: NOT OK | J5: NOT OK | K5: NOT OK | L5: NOT OK | M5: NOT OK | N5: NOT OK | O5: NOT OK | P5: NOT OK | Q5: NOT OK | R5: OK | S5: OK | T5: OK | U5: OK | V5: OK | W5: OK | X5: OK | Y5: OK | Z5: OK | AA5: OK | AB5: OK | AC5: NOT OK | AD5: NOT OK | AE5: NOT OK | AF5: NOT OK | AG5: NOT OK | AH5: NOT OK | AI5: NOT OK | AJ5: NOT OK | AK5: NOT OK | AL5: OK | AM5: OK | AN5: OK | AP5: NOT OK | BB5: Test Anaswer | LR5: Not Good Site | LS5: https://drive.google.com/open?id=1DOC9z7z08goOzWXp3yRuPEDarGkwAhsr
A6: 46174.114 | B6: Test Test 2 | C6: 6 | D6: Podium | E6: E | F6: Putty Work | EB6: OK | EC6: OK | EE6: NOT OK | EH6: OK | EQ6: test | LR6: test | LS6: https://drive.google.com/open?id=1KEC4BMqwegLIs7bFd7daXWf2LvGaHxk9
A7: 46174.148 | B7: ABC | C7: 7 | D7: 3 | E7: F | F7: RCC Work | G7: OK | H7: OK | I7: OK | J7: OK | K7: OK | BB7: kkk
A8: 46174.15 | B8: AB | C8: 1 | D8: 1 | E8: A | F8: Excavation & Earthwork | BT8: OK | BU8: OK | BV8: OK | BW8: OK | BX8: OK | BY8: OK | BZ8: OK | CA8: OK | CB8: OK | CC8: OK | CD8: OK | CE8: A | LR8: A | LS8: https://drive.google.com/open?id=1m226tGmrBub-mJfyiZP7HXv3VJrsRGNY
A9: 46174.161 | B9: Ayush | C9: 11 | D9: 13 | E9: D | F9: Plumbing Work | FY9: NOT OK | FZ9: NOT OK | GA9: NOT OK | GB9: NOT OK | GC9: NOT OK | GD9: NOT OK | GE9: NOT OK | GF9: NOT OK | GG9: NOT OK | GH9: NOT OK | GI9: NOT OK | GJ9: NOT OK | GK9: NOT OK | GL9: NOT OK | GM9: NOT OK | GN9: NOT OK | GO9: NOT OK | GP9: NOT OK | GQ9: NOT OK | GR9: NOT OK | GS9: NOT OK | GT9: NOT OK | GU9: NOT OK | GV9: NOT OK | GW9: NOT OK | GX9: NOT OK | GY9: NOT OK | GZ9: NOT OK | HA9: NOT OK | HB9: NOT OK | HC9: NOT OK | HD9: Plumbing Test | LR9: Not Good Work
A10: 46174.163 | B10: Rishi Sir | C10: 10 | D10: 10 | E10: D | F10: Tile Work | DD10: OK | DE10: OK | DF10: OK | DG10: OK | DH10: OK | DI10: OK | DJ10: OK | DK10: Pending | DL10: Pending | DM10: Pending | DN10: Pending | DO10: OK | DP10: OK | DQ10: OK | DR10: OK | DS10: OK | DT10: OK | DU10: OK | DV10: OK | DW10: OK | DX10: OK | DY10: OK | DZ10: Very nice | LR10: Not upto the mark | LS10: https://drive.google.com/open?id=13XVgqG9jXvpkjaFgga7vN_XAM2uJnP12
A11: 46174.173 | B11: Test Mekesh | C11: 9 | D11: 5 | E11: C | F11: False Ceiling Work | HE11: OK | HF11: OK | HG11: OK | HH11: OK | HI11: OK | HJ11: OK | HK11: OK | HL11: OK | HM11: OK | HN11: OK | HO11: OK | HP11: OK | HQ11: OK | HR11: OK | HS11: OK | HT11: OK | HU11: OK | HV11: OK | HW11: OK | HX11: OK | HY11: NOT OK | LS11: https://drive.google.com/open?id=1sjmVRAURimE4qfdx-Bb_4ZyJuKjHrCRN
A12: 46174.183 | B12: MB GHOSH | C12: 1 | D12: 2 | E12: B | F12: Masonry Work | BC12: OK | BD12: OK | BE12: OK | BF12: OK | BG12: OK
A13: 46174.193 | B13: test test 2 | C13: 6 | D13: Podium | E13: E | F13: Putty Work | EE13: OK
A14: 46174.212 | B14: Isha | C14: 15 | D14: 40 | E14: H | F14: Fire Fighting Work | KJ14: OK | KK14: NOT OK | KL14: Pending | KM14: N/A | KN14: Pending | KO14: NOT OK | KP14: OK | KQ14: NOT OK | KR14: Pending | KS14: N/A | KT14: Pending | KU14: NOT OK | KV14: OK | KW14: NOT OK | KX14: Pending | KY14: N/A | KZ14: Pending | LA14: NOT OK | LB14: OK | LC14: NOT OK | LD14: Pending | LE14: N/A | LF14: Pending | LG14: NOT OK | LH14: OK | LI14: NOT OK | LJ14: Pending | LK14: N/A | LL14: Pending | LM14: NOT OK | LN14: OK | LO14: NOT OK | LP14: Pending | LQ14: NA | LR14: AN | LS14: https://drive.google.com/open?id=1URMe4FRkDwzhFg7ekC9mNFriwp6W0iLv
A15: 46174.25 | B15: MNO | C15: 14 | D15: 39 | E15: G | F15: Landscape Development | JK15: OK | JL15: NOT OK | JM15: Pending | JN15: N/A | JO15: Pending | JP15: NOT OK | JQ15: OK | JR15: NOT OK | JS15: Pending | JT15: N/A | JU15: Pending | JV15: NOT OK | JW15: OK | JX15: NOT OK | JY15: Pending | JZ15: N/A | KA15: Pending | KB15: NOT OK | KC15: OK | KD15: NOT OK | KE15: Pending | KF15: N/A | KG15: Pending | KH15: NOT OK | KI15: YES | LR15: hahhs | LS15: https://drive.google.com/open?id=15lyshyfSsQ0xwhwjBJrYzFHCACAoNhGe
A16: 46174.945 | B16: Srayans | C16: 6 | D16: 7 | E16: E | F16: Putty Work | EA16: NOT OK | EB16: OK | EP16: Pending

Sheet CONFIG
A1: Blocks | B1: Floors | C1: Flats | D1: Status Options | E1: Rectified Options | F1: Block (drill) | G1: Floor (drill) | H1: Flat (drill) | I1: Category (drill)
A2: 1 | B2: Basement | C2: A | D2: OK | E2: Yes | F2: All | G2: All | H2: All | I2: All
A3: 2 | B3: Ground | C3: B | D3: NOT OK | E3: No | F3: 1 | G3: Basement | H3: A | I3: RCC Work
A4: 3 | B4: Podium | C4: C | D4: Pending | E4: In Progress | F4: 2 | G4: Ground | H4: B | I4: Masonry Work
A5: 4 | B5: 1 | C5: D | D5: N/A | E5: N/A | F5: 3 | G5: Podium | H5: C | I5: Excavation & Earthwork
A6: 5 | B6: 2 | C6: E | F6: 4 | G6: 1 | H6: D | I6: Plaster & Waterproofing
A7: 6 | B7: 3 | C7: F | F7: 5 | G7: 2 | H7: E | I7: Tile Work
A8: 7 | B8: 4 | C8: G | F8: 6 | G8: 3 | H8: F | I8: Putty Work
A9: 8 | B9: 5 | C9: H | F9: 7 | G9: 4 | H9: G | I9: Electrical Work
A10: 9 | B10: 6 | F10: 8 | G10: 5 | H10: H | I10: Plumbing Work
A11: 10 | B11: 7 | F11: 9 | G11: 6 | I11: False Ceiling Work
A12: 11 | B12: 8 | F12: 10 | G12: 7 | I12: Paint Work
A13: 12 | B13: 9 | F13: 11 | G13: 8 | I13: Landscape Development
A14: 13 | B14: 10 | F14: 12 | G14: 9 | I14: Fire Fighting Work
A15: 14 | B15: 11 | F15: 13 | G15: 10
A16: 15 | B16: 12 | F16: 14 | G16: 11
B17: 13 | F17: 15 | G17: 12
B18: 14 | G18: 13
B19: 15 | G19: 14
B20: 16 | G20: 15
B21: 17 | G21: 16
B22: 18 | G22: 17
B23: 19 | G23: 18
B24: 20 | G24: 19
B25: 21 | G25: 20
B26: 22 | G26: 21
B27: 23 | G27: 22
B28: 24 | G28: 23
B29: 25 | G29: 24
... B44: 40 | G44: 39
G45: 40

Sheet Setup & Sync Guide
A1: SETUP & SYNC GUIDE
A2: Mobile field inspection · live console · Excel + Google Sheets · cloud + intranet
B4: ✓ Supervisors inspect from their phone via a Google Form. Every submit updates the CONSOLE sheet instantly — flat-wise, block-wise, floor-wise and work-wise.
B6: 1. HOW A SUPERVISOR INSPECTS (on the phone)
B7: 1) Open the inspection link (share it on WhatsApp or save to the phone home screen).
B8: 2) Enter name, then pick Block, Floor and Flat from drop-downs.
B9: 3) Pick the work being inspected (e.g. Tile Work) — the form jumps to ONLY that checklist.
B10: 4) Tap OK / NOT OK / N/A for each check. Most take a few seconds.
B11: 5) On the last page, for every NOT OK item snap a photo and name the file with the check ID (e.g. TIL-005).
B12: 6) Press Submit. Done — it appears on the Console immediately.
B14: 2. ONE-TIME SETUP (about 10 minutes, do once)
B15: A) Put this workbook in Google Sheets: upload the .xlsx to Google Drive → right-click → Open with → Google Sheets (or File → Save as Google Sheets).
B16: B) In the Sheet: Extensions → Apps Script. Delete the sample code, paste the file "JainGroup_QC_FormBuilder.gs" provided with this workbook, and click Save.
B17: C) In the toolbar choose the function buildInspectionForm and click Run. Approve the permission prompt. It builds the whole form automatically and prints the links in View → Logs.
... B43: • Keep one master copy as the source of truth once it is on cloud / intranet.

Sheet Console
A1: JAIN GROUP | N1: =IF($B$11="All","*",$B$11) -> 6
A2: QUALITY CONTROL CONSOLE · LIVE INSPECTION MONITOR | N2: =IF($E$11="All","*",$E$11) -> Podium
A3: Updates automatically every time a supervisor submits an inspection from the field | N3: =IF($H$11="All","*",$H$11) -> E
N4: =IF($K$11="All","*",$K$11) -> Putty Work
A5: CHECKS LOGGED | C5: OK / PASSED | E5: DEFECTS (NOT OK) | G5: OPEN DEFECTS | I5: RECTIFIED | K5: PASS RATE
A6: =COUNTA('Inspection Log'!$G$2:$G$5000) -> 249 | C6: =COUNTIF('Inspection Log'!$I$2:$I$5000,"OK") -> 143 | E6: =COUNTIF('Inspection Log'!$I$2:$I$5000,"NOT OK") -> 73 | G6: =COUNTIF('Inspection Log'!$I$2:$I$5000,"NOT OK")-COUNTIFS('Inspection Log'!$I$2:$I$5000,"NOT OK",'Inspection Log'!$K$2:$K$5000,"Yes") -> 73 | I6: =COUNTIFS('Inspection Log'!$I$2:$I$5000,"NOT OK",'Inspection Log'!$K$2:$K$5000,"Yes") -> 0 | K6: =IFERROR(COUNTIF('Inspection Log'!$I$2:$I$5000,"OK")/(COUNTIF('Inspection Log'!$I$2:$I$5000,"OK")+COUNTIF('Inspection Log'!$I$2:$I$5000,"NOT OK")),0) -> 0.66203704
A9: DRILL-DOWN — pick any Block / Floor / Flat / Work Type
A10: Block | D10: Floor | G10: Flat | J10: Work Type
B11: 6 | E11: Podium | H11: E | K11: Putty Work
A12: Checks | C12: OK | E12: NOT OK | G12: Open | I12: Pass Rate
A13: =COUNTIFS('Inspection Log'!$C$2:$C$5000,$N$1,'Inspection Log'!$D$2:$D$5000,$N$2,'Inspection Log'!$E$2:$E$5000,$N$3,'Inspection Log'!$F$2:$F$5000,$N$4) -> 5 | C13: =COUNTIFS('Inspection Log'!$C$2:$C$5000,$N$1,'Inspection Log'!$D$2:$D$5000,$N$2,'Inspection Log'!$E$2:$E$5000,$N$3,'Inspection Log'!$F$2:$F$5000,$N$4,'Inspection Log'!$I$2:$I$5000,"OK") -> 4 | E13: =COUNTIFS('Inspection Log'!$C$2:$C$5000,$N$1,'Inspection Log'!$D$2:$D$5000,$N$2,'Inspection Log'!$E$2:$E$5000,$N$3,'Inspection Log'!$F$2:$F$5000,$N$4,'Inspection Log'!$I$2:$I$5000,"NOT OK") -> 1 | G13: =COUNTIFS('Inspection Log'!$C$2:$C$5000,$N$1,'Inspection Log'!$D$2:$D$5000,$N$2,'Inspection Log'!$E$2:$E$5000,$N$3,'Inspection Log'!$F$2:$F$5000,$N$4,'Inspection Log'!$I$2:$I$5000,"NOT OK")-COUNTIFS('Inspection Log'!$C$2:$C$5000,$N$1,'Inspection Log'!$D$2:$D$5000,$N$2,'Inspection Log'!$E$2:$E$5000,$N$3,'Inspection Log'!$F$2:$F$5000,$N$4,'Inspection Log'!$I$2:$I$5000,"NOT OK",'Inspection Log'!$K$2:$K$5000,"Yes") -> 1 | I13: =IFERROR(COUNTIFS('Inspection Log'!$C$2:$C$5000,$N$1,'Inspection Log'!$D$2:$D$5000,$N$2,'Inspection Log'!$E$2:$E$5000,$N$3,'Inspection Log'!$F$2:$F$5000,$N$4,'Inspection Log'!$I$2:$I$5000,"OK")/(COUNTIFS('Inspection Log'!$C$2:$C$5000,$N$1,'Inspection Log'!$D$2:$D$5000,$N$2,'Inspection Log'!$E$2:$E$5000,$N$3,'Inspection Log'!$F$2:$F$5000,$N$4,'Inspection Log'!$I$2:$I$5000,"OK")+COUNTIFS('Inspection Log'!$C$2:$C$5000,$N$1,'Inspection Log'!$D$2:$D$5000,$N$2,'Inspection Log'!$E$2:$E$5000,$N$3,'Inspection Log'!$F$2:$F$5000,$N$4,'Inspection Log'!$I$2:$I$5000,"NOT OK")),0) -> 0.8
A15: STATUS BY BLOCK | G15: STATUS BY WORK CATEGORY
A16: Block | B16: Checks | C16: OK | D16: NOT OK | E16: Open | F16: Pass % | G16: Category | I16: Checks | J16: OK | K16: NOT OK | L16: Pass %
A17: 1 | B17: =COUNTIF('Inspection Log'!$C$2:$C$5000,$A17) -> 16 | C17: =COUNTIFS('Inspection Log'!$C$2:$C$5000,$A17,'Inspection Log'!$I$2:$I$5000,"OK") -> 16 | D17: =COUNTIFS('Inspection Log'!$C$2:$C$5000,$A17,'Inspection Log'!$I$2:$I$5000,"NOT OK") -> 0 | E17: =COUNTIFS('Inspection Log'!$C$2:$C$5000,$A17,'Inspection Log'!$I$2:$I$5000,"NOT OK")-COUNTIFS('Inspection Log'!$C$2:$C$5000,$A17,'Inspection Log'!$I$2:$I$5000,"NOT OK",'Inspection Log'!$K$2:$K$5000,"Yes") -> 0 | F17: =IFERROR(C17/(C17+D17),0) -> 1 | G17: RCC Work | I17: =COUNTIFS('Inspection Log'!$F$2:$F$5000,"RCC Work") -> 70 | J17: =COUNTIFS('Inspection Log'!$F$2:$F$5000,"RCC Work",'Inspection Log'!$I$2:$I$5000,"OK") -> 49 | K17: =COUNTIFS('Inspection Log'!$F$2:$F$5000,"RCC Work",'Inspection Log'!$I$2:$I$5000,"NOT OK") -> 21 | L17: =IFERROR(J17/(J17+K17),0) -> 0.7
A18: 2 | B18: =COUNTIF('Inspection Log'!$C$2:$C$5000,$A18) -> 35 | C18: =COUNTIFS('Inspection Log'!$C$2:$C$5000,$A18,'Inspection Log'!$I$2:$I$5000,"OK") -> 14 | D18: =COUNTIFS('Inspection Log'!$C$2:$C$5000,$A18,'Inspection Log'!$I$2:$I$5000,"NOT OK") -> 21 | E18: =COUNTIFS('Inspection Log'!$C$2:$C$5000,$A18,'Inspection Log'!$I$2:$I$5000,"NOT OK")-COUNTIFS('Inspection Log'!$C$2:$C$5000,$A18,'Inspection Log'!$I$2:$I$5000,"NOT OK",'Inspection Log'!$K$2:$K$5000,"Yes") -> 21 | F18: =IFERROR(C18/(C18+D18),0) -> 0.4 | G18: Masonry Work | I18: =COUNTIFS('Inspection Log'!$F$2:$F$5000,"Masonry Work") -> 5 | J18: =COUNTIFS('Inspection Log'!$F$2:$F$5000,"Masonry Work",'Inspection Log'!$I$2:$I$5000,"OK") -> 5 | K18: =COUNTIFS('Inspection Log'!$F$2:$F$5000,"Masonry Work",'Inspection Log'!$I$2:$I$5000,"NOT OK") -> 0 | L18: =IFERROR(J18/(J18+K18),0) -> 1
A19: 3 | B19: =COUNTIF('Inspection Log'!$C$2:$C$5000,$A19) -> 0 | C19: =COUNTIFS('Inspection Log'!$C$2:$C$5000,$A19,'Inspection Log'!$I$2:$I$5000,"OK") -> 0 | D19: =COUNTIFS('Inspection Log'!$C$2:$C$5000,$A19,'Inspection Log'!$I$2:$I$5000,"NOT OK") -> 0 | E19: =COUNTIFS('Inspection Log'!$C$2:$C$5000,$A19,'Inspection Log'!$I$2:$I$5000,"NOT OK")-COUNTIFS('Inspection Log'!$C$2:$C$5000,$A19,'Inspection Log'!$I$2:$I$5000,"NOT OK",'Inspection Log'!$K$2:$K$5000,"Yes") -> 0 | F19: =IFERROR(C19/(C19+D19),0) -> 0 | G19: Excavation & Earthwork | I19: =COUNTIFS('Inspection Log'!$F$2:$F$5000,"Excavation & Earthwork") -> 11 | J19: =COUNTIFS('Inspection Log'!$F$2:$F$5000,"Excavation & Earthwork",'Inspection Log'!$I$2:$I$5000,"OK") -> 11 | K19: =COUNTIFS('Inspection Log'!$F$2:$F$5000,"Excavation & Earthwork",'Inspection Log'!$I$2:$I$5000,"NOT OK") -> 0 | L19: =IFERROR(J19/(J19+K19),0) -> 1
A20: 4 | B20: =COUNTIF('Inspection Log'!$C$2:$C$5000,$A20) -> 30 | C20: =COUNTIFS('Inspection Log'!$C$2:$C$5000,$A20,'Inspection Log'!$I$2:$I$5000,"OK") -> 30 | D20: =COUNTIFS('Inspection Log'!$C$2:$C$5000,$A20,'Inspection Log'!$I$2:$I$5000,"NOT OK") -> 0 | E20: =COUNTIFS('Inspection Log'!$C$2:$C$5000,$A20,'Inspection Log'!$I$2:$I$5000,"NOT OK")-COUNTIFS('Inspection Log'!$C$2:$C$5000,$A20,'Inspection Log'!$I$2:$I$5000,"NOT OK",'Inspection Log'!$K$2:$K$5000,"Yes") -> 0 | F20: =IFERROR(C20/(C20+D20),0) -> 1 | G20: Plaster & Waterproofing | I20: =COUNTIFS('Inspection Log'!$F$2:$F$5000,"Plaster & Waterproofing") -> 0 | J20: =COUNTIFS('Inspection Log'!$F$2:$F$5000,"Plaster & Waterproofing",'Inspection Log'!$I$2:$I$5000,"OK") -> 0 | K20: =COUNTIFS('Inspection Log'!$F$2:$F$5000,"Plaster & Waterproofing",'Inspection Log'!$I$2:$I$5000,"NOT OK") -> 0 | L20: =IFERROR(J20/(J20+K20),0) -> 0
A21: 5 | B21: =COUNTIF('Inspection Log'!$C$2:$C$5000,$A21) -> 24 | C21: =COUNTIFS('Inspection Log'!$C$2:$C$5000,$A21,'Inspection Log'!$I$2:$I$5000,"OK") -> 24 | D21: =COUNTIFS('Inspection Log'!$C$2:$C$5000,$A21,'Inspection Log'!$I$2:$I$5000,"NOT OK") -> 0 | E21: =COUNTIFS('Inspection Log'!$C$2:$C$5000,$A21,'Inspection Log'!$I$2:$I$5000,"NOT OK")-COUNTIFS('Inspection Log'!$C$2:$C$5000,$A21,'Inspection Log'!$I$2:$I$5000,"NOT OK",'Inspection Log'!$K$2:$K$5000,"Yes") -> 0 | F21: =IFERROR(C21/(C21+D21),0) -> 1 | G21: Tile Work | I21: =COUNTIFS('Inspection Log'!$F$2:$F$5000,"Tile Work") -> 22 | J21: =COUNTIFS('Inspection Log'!$F$2:$F$5000,"Tile Work",'Inspection Log'!$I$2:$I$5000,"OK") -> 18 | K21: =COUNTIFS('Inspection Log'!$F$2:$F$5000,"Tile Work",'Inspection Log'!$I$2:$I$5000,"NOT OK") -> 0 | L21: =IFERROR(J21/(J21+K21),0) -> 1
A22: 6 | B22: =COUNTIF('Inspection Log'!$C$2:$C$5000,$A22) -> 8 | C22: =COUNTIFS('Inspection Log'!$C$2:$C$5000,$A22,'Inspection Log'!$I$2:$I$5000,"OK") -> 5 | D22: =COUNTIFS('Inspection Log'!$C$2:$C$5000,$A22,'Inspection Log'!$I$2:$I$5000,"NOT OK") -> 2 | E22: =COUNTIFS('Inspection Log'!$C$2:$C$5000,$A22,'Inspection Log'!$I$2:$I$5000,"NOT OK")-COUNTIFS('Inspection Log'!$C$2:$C$5000,$A22,'Inspection Log'!$I$2:$I$5000,"NOT OK",'Inspection Log'!$K$2:$K$5000,"Yes") -> 2 | F22: =IFERROR(C22/(C22+D22),0) -> 0.71428571 | G22: Putty Work | I22: =COUNTIFS('Inspection Log'!$F$2:$F$5000,"Putty Work") -> 8 | J22: =COUNTIFS('Inspection Log'!$F$2:$F$5000,"Putty Work",'Inspection Log'!$I$2:$I$5000,"OK") -> 5 | K22: =COUNTIFS('Inspection Log'!$F$2:$F$5000,"Putty Work",'Inspection Log'!$I$2:$I$5000,"NOT OK") -> 2 | L22: =IFERROR(J22/(J22+K22),0) -> 0.71428571
A23: 7 | B23: =COUNTIF('Inspection Log'!$C$2:$C$5000,$A23) -> 5 | C23: =COUNTIFS('Inspection Log'!$C$2:$C$5000,$A23,'Inspection Log'!$I$2:$I$5000,"OK") -> 5 | D23: =COUNTIFS('Inspection Log'!$C$2:$C$5000,$A23,'Inspection Log'!$I$2:$I$5000,"NOT OK") -> 0 | E23: =COUNTIFS('Inspection Log'!$C$2:$C$5000,$A23,'Inspection Log'!$I$2:$I$5000,"NOT OK")-COUNTIFS('Inspection Log'!$C$2:$C$5000,$A23,'Inspection Log'!$I$2:$I$5000,"NOT OK",'Inspection Log'!$K$2:$K$5000,"Yes") -> 0 | F23: =IFERROR(C23/(C23+D23),0) -> 1 | G23: Electrical Work | I23: =COUNTIFS('Inspection Log'!$F$2:$F$5000,"Electrical Work") -> 0 | J23: =COUNTIFS('Inspection Log'!$F$2:$F$5000,"Electrical Work",'Inspection Log'!$I$2:$I$5000,"OK") -> 0 | K23: =COUNTIFS('Inspection Log'!$F$2:$F$5000,"Electrical Work",'Inspection Log'!$I$2:$I$5000,"NOT OK") -> 0 | L23: =IFERROR(J23/(J23+K23),0) -> 0
A24: 8 | B24: =COUNTIF('Inspection Log'!$C$2:$C$5000,$A24) -> 0 | C24: =COUNTIFS('Inspection Log'!$C$2:$C$5000,$A24,'Inspection Log'!$I$2:$I$5000,"OK") -> 0 | D24: =COUNTIFS('Inspection Log'!$C$2:$C$5000,$A24,'Inspection Log'!$I$2:$I$5000,"NOT OK") -> 0 | E24: =COUNTIFS('Inspection Log'!$C$2:$C$5000,$A24,'Inspection Log'!$I$2:$I$5000,"NOT OK")-COUNTIFS('Inspection Log'!$C$2:$C$5000,$A24,'Inspection Log'!$I$2:$I$5000,"NOT OK",'Inspection Log'!$K$2:$K$5000,"Yes") -> 0 | F24: =IFERROR(C24/(C24+D24),0) -> 0 | G24: Plumbing Work | I24: =COUNTIFS('Inspection Log'!$F$2:$F$5000,"Plumbing Work") -> 31 | J24: =COUNTIFS('Inspection Log'!$F$2:$F$5000,"Plumbing Work",'Inspection Log'!$I$2:$I$5000,"OK") -> 0 | K24: =COUNTIFS('Inspection Log'!$F$2:$F$5000,"Plumbing Work",'Inspection Log'!$I$2:$I$5000,"NOT OK") -> 31 | L24: =IFERROR(J24/(J24+K24),0) -> 0
A25: 9 | B25: =COUNTIF('Inspection Log'!$C$2:$C$5000,$A25) -> 21 | C25: =COUNTIFS('Inspection Log'!$C$2:$C$5000,$A25,'Inspection Log'!$I$2:$I$5000,"OK") -> 21 | D25: =COUNTIFS('Inspection Log'!$C$2:$C$5000,$A25,'Inspection Log'!$I$2:$I$5000,"NOT OK") -> 0 | E25: =COUNTIFS('Inspection Log'!$C$2:$C$5000,$A25,'Inspection Log'!$I$2:$I$5000,"NOT OK")-COUNTIFS('Inspection Log'!$C$2:$C$5000,$A25,'Inspection Log'!$I$2:$I$5000,"NOT OK",'Inspection Log'!$K$2:$K$5000,"Yes") -> 0 | F25: =IFERROR(C25/(C25+D25),0) -> 1 | G25: False Ceiling Work | I25: =COUNTIFS('Inspection Log'!$F$2:$F$5000,"False Ceiling Work") -> 21 | J25: =COUNTIFS('Inspection Log'!$F$2:$F$5000,"False Ceiling Work",'Inspection Log'!$I$2:$I$5000,"OK") -> 21 | K25: =COUNTIFS('Inspection Log'!$F$2:$F$5000,"False Ceiling Work",'Inspection Log'!$I$2:$I$5000,"NOT OK") -> 0 | L25: =IFERROR(J25/(J25+K25),0) -> 1
A26: 10 | B26: =COUNTIF('Inspection Log'!$C$2:$C$5000,$A26) -> 22 | C26: =COUNTIFS('Inspection Log'!$C$2:$C$5000,$A26,'Inspection Log'!$I$2:$I$5000,"OK") -> 18 | D26: =COUNTIFS('Inspection Log'!$C$2:$C$5000,$A26,'Inspection Log'!$I$2:$I$5000,"NOT OK") -> 0 | E26: =COUNTIFS('Inspection Log'!$C$2:$C$5000,$A26,'Inspection Log'!$I$2:$I$5000,"NOT OK")-COUNTIFS('Inspection Log'!$C$2:$C$5000,$A26,'Inspection Log'!$I$2:$I$5000,"NOT OK",'Inspection Log'!$K$2:$K$5000,"Yes") -> 0 | F26: =IFERROR(C26/(C26+D26),0) -> 1 | G26: Paint Work | I26: =COUNTIFS('Inspection Log'!$F$2:$F$5000,"Paint Work") -> 0 | J26: =COUNTIFS('Inspection Log'!$F$2:$F$5000,"Paint Work",'Inspection Log'!$I$2:$I$5000,"OK") -> 0 | K26: =COUNTIFS('Inspection Log'!$F$2:$F$5000,"Paint Work",'Inspection Log'!$I$2:$I$5000,"NOT OK") -> 0 | L26: =IFERROR(J26/(J26+K26),0) -> 0
A27: 11 | B27: =COUNTIF('Inspection Log'!$C$2:$C$5000,$A27) -> 31 | C27: =COUNTIFS('Inspection Log'!$C$2:$C$5000,$A27,'Inspection Log'!$I$2:$I$5000,"OK") -> 0 | D27: =COUNTIFS('Inspection Log'!$C$2:$C$5000,$A27,'Inspection Log'!$I$2:$I$5000,"NOT OK") -> 31 | E27: =COUNTIFS('Inspection Log'!$C$2:$C$5000,$A27,'Inspection Log'!$I$2:$I$5000,"NOT OK")-COUNTIFS('Inspection Log'!$C$2:$C$5000,$A27,'Inspection Log'!$I$2:$I$5000,"NOT OK",'Inspection Log'!$K$2:$K$5000,"Yes") -> 31 | F27: =IFERROR(C27/(C27+D27),0) -> 0 | G27: Landscape Development | I27: =COUNTIFS('Inspection Log'!$F$2:$F$5000,"Landscape Development") -> 48 | J27: =COUNTIFS('Inspection Log'!$F$2:$F$5000,"Landscape Development",'Inspection Log'!$I$2:$I$5000,"OK") -> 28 | K27: =COUNTIFS('Inspection Log'!$F$2:$F$5000,"Landscape Development",'Inspection Log'!$I$2:$I$5000,"NOT OK") -> 8 | L27: =IFERROR(J27/(J27+K27),0) -> 0.77777778
A28: 12 | B28: =COUNTIF('Inspection Log'!$C$2:$C$5000,$A28) -> 0 | C28: =COUNTIFS('Inspection Log'!$C$2:$C$5000,$A28,'Inspection Log'!$I$2:$I$5000,"OK") -> 0 | D28: =COUNTIFS('Inspection Log'!$C$2:$C$5000,$A28,'Inspection Log'!$I$2:$I$5000,"NOT OK") -> 0 | E28: =COUNTIFS('Inspection Log'!$C$2:$C$5000,$A28,'Inspection Log'!$I$2:$I$5000,"NOT OK")-COUNTIFS('Inspection Log'!$C$2:$C$5000,$A28,'Inspection Log'!$I$2:$I$5000,"NOT OK",'Inspection Log'!$K$2:$K$5000,"Yes") -> 0 | F28: =IFERROR(C28/(C28+D28),0) -> 0 | G28: Fire Fighting Work | I28: =COUNTIFS('Inspection Log'!$F$2:$F$5000,"Fire Fighting Work") -> 33 | J28: =COUNTIFS('Inspection Log'!$F$2:$F$5000,"Fire Fighting Work",'Inspection Log'!$I$2:$I$5000,"OK") -> 6 | K28: =COUNTIFS('Inspection Log'!$F$2:$F$5000,"Fire Fighting Work",'Inspection Log'!$I$2:$I$5000,"NOT OK") -> 11 | L28: =IFERROR(J28/(J28+K28),0) -> 0.35294118
A29: 13 | B29: =COUNTIF('Inspection Log'!$C$2:$C$5000,$A29) -> 0 | C29: =COUNTIFS('Inspection Log'!$C$2:$C$5000,$A29,'Inspection Log'!$I$2:$I$5000,"OK") -> 0 | D29: =COUNTIFS('Inspection Log'!$C$2:$C$5000,$A29,'Inspection Log'!$I$2:$I$5000,"NOT OK") -> 0 | E29: =COUNTIFS('Inspection Log'!$C$2:$C$5000,$A29,'Inspection Log'!$I$2:$I$5000,"NOT OK")-COUNTIFS('Inspection Log'!$C$2:$C$5000,$A29,'Inspection Log'!$I$2:$I$5000,"NOT OK",'Inspection Log'!$K$2:$K$5000,"Yes") -> 0 | F29: =IFERROR(C29/(C29+D29),0) -> 0
A30: 14 | B30: =COUNTIF('Inspection Log'!$C$2:$C$5000,$A30) -> 24 | C30: =COUNTIFS('Inspection Log'!$C$2:$C$5000,$A30,'Inspection Log'!$I$2:$I$5000,"OK") -> 4 | D30: =COUNTIFS('Inspection Log'!$C$2:$C$5000,$A30,'Inspection Log'!$I$2:$I$5000,"NOT OK") -> 8 | E30: =COUNTIFS('Inspection Log'!$C$2:$C$5000,$A30,'Inspection Log'!$I$2:$I$5000,"NOT OK")-COUNTIFS('Inspection Log'!$C$2:$C$5000,$A30,'Inspection Log'!$I$2:$I$5000,"NOT OK",'Inspection Log'!$K$2:$K$5000,"Yes") -> 8 | F30: =IFERROR(C30/(C30+D30),0) -> 0.33333333
A31: 15 | B31: =COUNTIF('Inspection Log'!$C$2:$C$5000,$A31) -> 33 | C31: =COUNTIFS('Inspection Log'!$C$2:$C$5000,$A31,'Inspection Log'!$I$2:$I$5000,"OK") -> 6 | D31: =COUNTIFS('Inspection Log'!$C$2:$C$5000,$A31,'Inspection Log'!$I$2:$I$5000,"NOT OK") -> 11 | E31: =COUNTIFS('Inspection Log'!$C$2:$C$5000,$A31,'Inspection Log'!$I$2:$I$5000,"NOT OK")-COUNTIFS('Inspection Log'!$C$2:$C$5000,$A31,'Inspection Log'!$I$2:$I$5000,"NOT OK",'Inspection Log'!$K$2:$K$5000,"Yes") -> 11 | F31: =IFERROR(C31/(C31+D31),0) -> 0.35294118
A33: OPEN DEFECTS (Block · Floor · Flat · Item · Check · Photo)
A34: Block | B34: Floor | C34: Flat | D34: Category | E34: Item ID | F34: Inspection Check | G34: Status | H34: Defect Photo
A35: =IFERROR(__xludf.DUMMYFUNCTION("IFERROR(filter('Inspection Log'!C2:J5000,('Inspection Log'!I2:I5000=""NOT OK"")*('Inspection Log'!K2:K5000<>""Yes"")),""No open defects logged yet — all clear"")"),"#REF!") -> #REF!
A48: QUICK NAVIGATION
A49: 📋 Checklist Master (questions) | D49: 🗂 Inspection Log | G49: 🎬 Training Library | J49: ⚙ Setup & Sync Guide

Sheet Master Checklist
A1: Block | B1: Floor | C1: Flat | D1: Item ID | E1: Work Category | F1: Stage | G1: Inspection Check | H1: Acceptance Criteria / Standard | I1: Status | J1: Date | K1: Checked By | L1: Remarks / Observations | M1: Training Video / Reference | N1: Source Files | O1: Ageing (Days) | P1: Defect Photo | Q1: Rectified? | R1: Rectified Date | S1: Rectified Photo | T1: Rectification Remarks
D2: RCC-001 | E2: RCC Work | F2: Post-pour | G2: Dimensions: length, breadth, depth as per drawing. | H2: Tolerance ±5mm linear; ±10mm in level. | I2: Pending | N2: CHECKLIST.xlsx; Quality Checklist.xlsx | O2: =IF($I2="OK","",IF($I2="N/A","",IF($J2="","",MAX(0,TODAY()-$J2))))
D3: RCC-002 | E3: RCC Work | F3: Reinforcement | G3: Check is the bar bending schedule is prepared and approved by the site Engineer. | H3: Requirement verified and observation recorded as per approved project specification. | I3: Pending | M3: ▶ Watch (2 videos) | N3: CHECKLIST.xlsx | O3: =IF($I3="OK","",IF($I3="N/A","",IF($J3="","",MAX(0,TODAY()-$J3))))
D4: RCC-003 | E4: RCC Work | F4: Reinforcement | G4: Check for correct cutting & bending of bars as per approved BBS. | H4: Requirement verified and observation recorded as per approved project specification. | I4: Pending | M4: ▶ Watch (2 videos) | N4: CHECKLIST.xlsx | O4: =IF($I4="OK","",IF($I4="N/A","",IF($J4="","",MAX(0,TODAY()-$J4))))
D5: RCC-004 | E5: RCC Work | F5: Reinforcement | G5: Check bar diameter, shapes of bar, dimension of bars & number of bars as per BBS. | H5: Requirement verified and observation recorded as per approved project specification. | I5: Pending | M5: ▶ Watch (2 videos) | N5: CHECKLIST.xlsx | O5: =IF($I5="OK","",IF($I5="N/A","",IF($J5="","",MAX(0,TODAY()-$J5))))
D6: RCC-005 | E6: RCC Work | F6: Reinforcement | G6: Check identification tags is attached. | H6: Requirement verified and observation recorded as per approved project specification. | I6: Pending | M6: ▶ Watch (2 videos) | N6: CHECKLIST.xlsx | O6: =IF($I6="OK","",IF($I6="N/A","",IF($J6="","",MAX(0,TODAY()-$J6))))
D7: RCC-006 | E7: RCC Work | F7: Reinforcement | G7: Check for cleanliness of bars from any oil, grease, soil & rust. | H7: Requirement verified and observation recorded as per approved project specification. | I7: Pending | M7: ▶ Watch (2 videos) | N7: CHECKLIST.xlsx | O7: =IF($I7="OK","",IF($I7="N/A","",IF($J7="","",MAX(0,TODAY()-$J7))))
D8: RCC-007 | E8: RCC Work | F8: Reinforcement | G8: Check for satisfactory tying of reinforcement with binding wire. | H8: Requirement verified and observation recorded as per approved project specification. | I8: Pending | M8: ▶ Watch (2 videos) | N8: CHECKLIST.xlsx | O8: =IF($I8="OK","",IF($I8="N/A","",IF($J8="","",MAX(0,TODAY()-$J8))))
D9: RCC-008 | E9: RCC Work | F9: Reinforcement | G9: Check for location of service conduits. | H9: Requirement verified and observation recorded as per approved project specification. | I9: Pending | M9: ▶ Watch (2 videos) | N9: CHECKLIST.xlsx | O9: =IF($I9="OK","",IF($I9="N/A","",IF($J9="","",MAX(0,TODAY()-$J9))))
D10: RCC-009 | E10: RCC Work | F10: Reinforcement | G10: Check for readiness of reinforcement for release for concreting. | H10: Requirement verified and observation recorded as per approved project specification. | I10: Pending | M10: ▶ Watch (2 videos) | N10: CHECKLIST.xlsx | O10: =IF($I10="OK","",IF($I10="N/A","",IF($J10="","",MAX(0,TODAY()-$J10))))
D11: RCC-010 | E11: RCC Work | F11: Concrete Pour | G11: Slump test at pour location. | H11: Within specified range (75–125mm typical); record value. | I11: Pending | M11: ▶ Watch Video | N11: CHECKLIST.xlsx; Quality Checklist.xlsx | O11: =IF($I11="OK","",IF($I11="N/A","",IF($J11="","",MAX(0,TODAY()-$J11))))
D12: RCC-011 | E12: RCC Work | F12: Concreting | G12: Is continuous flow of concrete ensured. | H12: Requirement verified and observation recorded as per approved project specification. | I12: Pending | N12: CHECKLIST.xlsx | O12: =IF($I12="OK","",IF($I12="N/A","",IF($J12="","",MAX(0,TODAY()-$J12))))
D13: RCC-012 | E13: RCC Work | F13: Concreting | G13: Check for transportation & placement of concrete. Is it ok? | H13: Requirement verified and observation recorded as per approved project specification. | I13: Pending | N13: CHECKLIST.xlsx | O13: =IF($I13="OK","",IF($I13="N/A","",IF($J13="","",MAX(0,TODAY()-$J13))))
D14: RCC-013 | E14: RCC Work | F14: Concreting | G14: Check whether vibration being done till concrete packs tightly against all surface, reinforcement and embedments. | H14: Requirement verified and observation recorded as per approved project specification. | I14: Pending | M14: ▶ Watch (2 videos) | N14: CHECKLIST.xlsx | O14: =IF($I14="OK","",IF($I14="N/A","",IF($J14="","",MAX(0,TODAY()-$J14))))
D15: RCC-014 | E15: RCC Work | F15: Concreting | G15: Is blending of concrete poured in separated layers being ensured? | H15: Requirement verified and observation recorded as per approved project specification. | I15: Pending | N15: CHECKLIST.xlsx | O15: =IF($I15="OK","",IF($I15="N/A","",IF($J15="","",MAX(0,TODAY()-$J15))))
D16: RCC-015 | E16: RCC Work | F16: Concreting | G16: Is concrete consumed within initial setting time of cement. | H16: Requirement verified and observation recorded as per approved project specification. | I16: Pending | N16: CHECKLIST.xlsx | O16: =IF($I16="OK","",IF($I16="N/A","",IF($J16="","",MAX(0,TODAY()-$J16))))
D17: RCC-016 | E17: RCC Work | F17: Concreting | G17: Check for positions of construction joint. Is it ok? | H17: Requirement verified and observation recorded as per approved project specification. | I17: Pending | N17: CHECKLIST.xlsx | O17: =IF($I17="OK","",IF($I17="N/A","",IF($J17="","",MAX(0,TODAY()-$J17))))
D18: RCC-017 | E18: RCC Work | F18: Concreting | G18: Check for leveling and finishing of concrete surface. | H18: Line, level, and plumb are within project tolerance. | I18: Pending | N18: CHECKLIST.xlsx | O18: =IF($I18="OK","",IF($I18="N/A","",IF($J18="","",MAX(0,TODAY()-$J18))))
D19: RCC-018 | E19: RCC Work | F19: Concreting | G19: Check the quantity of concrete of poured match with theoretical qty. | H19: Requirement verified and observation recorded as per approved project specification. | I19: Pending | N19: CHECKLIST.xlsx | O19: =IF($I19="OK","",IF($I19="N/A","",IF($J19="","",MAX(0,TODAY()-$J19))))
D20: RCC-019 | E20: RCC Work | F20: Concreting | G20: Check the start time and end time of concreting. | H20: Requirement verified and observation recorded as per approved project specification. | I20: Pending | N20: CHECKLIST.xlsx | O20: =IF($I20="OK","",IF($I20="N/A","",IF($J20="","",MAX(0,TODAY()-$J20))))
D21: RCC-020 | E21: RCC Work | F21: Concrete Pour | G21: Cube samples cast (6 numbers / 50 m³). | H21: Stored & cured per IS 516; tagged with date/location. Also verify: ≥ 65% (7d) & 100% (28d) of design strength. | I21: Pending | M21: ▶ Watch (2 videos) | N21: CHECKLIST.xlsx; Quality Checklist.xlsx | O21: =IF($I21="OK","",IF($I21="N/A","",IF($J21="","",MAX(0,TODAY()-$J21))))
D22: RCC-021 | E22: RCC Work | F22: Pre-pour: Shuttering | G22: Shuttering material (ply / steel) condition. | H22: No damage, no warping; ply min 12mm, oiled. | I22: Pending | M22: ▶ Watch (3 videos) | N22: Quality Checklist.xlsx | O22: =IF($I22="OK","",IF($I22="N/A","",IF($J22="","",MAX(0,TODAY()-$J22))))
D23: RCC-022 | E23: RCC Work | F23: Pre-pour: Shuttering | G23: Line, level & plumb of formwork. | H23: Plumb deviation ≤ 1:1000; level within ±3mm/m. | I23: Pending | M23: ▶ Watch Video | N23: Quality Checklist.xlsx | O23: =IF($I23="OK","",IF($I23="N/A","",IF($J23="","",MAX(0,TODAY()-$J23))))
D24: RCC-023 | E24: RCC Work | F24: Pre-pour: Shuttering | G24: Props, bracing & supports adequacy. | H24: As per design; no deflection under load. | I24: Pending | M24: ▶ Watch Video | N24: Quality Checklist.xlsx | O24: =IF($I24="OK","",IF($I24="N/A","",IF($J24="","",MAX(0,TODAY()-$J24))))
